<?xml version='1.0' encoding='utf-8'?>
<robot name="ability_hand">
   <link name="hand_base_link" /><link name="hand_base">
      <visual name="wrist_mesh">
         <origin rpy="0 0 0" xyz="0 0 0" />
         <geometry>
            <mesh filename="package://ah_urdf/models/wristmesh.STL" />
         </geometry>
      </visual>
      <inertial>
         <mass value="0.37511000" />
         <inertia ixx="3.76723021e-04" ixy="-2.33895460e-06" ixz="6.04325119e-06" iyy="4.67706269e-04" iyz="5.04572726e-05" izz="1.77650714e-04" />
         <origin xyz="6.54520000e-04 -5.98838000e-03 5.07726500e-02" rpy="0 0 0" />
      </inertial>
      <visual name="palm_mesh">
         <origin rpy="3.14148426 -0.08848813 -3.14036612" xyz="-24.0476665e-3 3.78124745e-3 32.32964923e-3" />
         <geometry>
            <mesh filename="package://ah_urdf/models/FB_palm_ref_MIR.STL" />
         </geometry>
      </visual>
      <collision name="palm_mesh_coll">
         <origin rpy="3.14148426 -0.08848813 -3.14036612" xyz="-24.0476665e-3 3.78124745e-3 32.32964923e-3" />
         <geometry>
            <mesh filename="package://ah_urdf/models/palm_hull_mir.STL" />
         </geometry>
      </collision>
   </link>
   <link name="hand_index_L1">
      <inertial>
         <mass value="0.00636000" />
         <inertia ixx="2.85169621e-07" ixy="1.21454801e-08" ixz="2.02098452e-09" iyy="9.77683041e-07" iyz="-2.87547802e-10" izz="1.05411544e-06" />
         <origin xyz="1.77549969e-02 -2.13867669e-04 -2.02851433e-05" rpy="0 0 0" />
      </inertial>
      <visual name="hand_index_mesh_1">
         <origin rpy="0 0 0" xyz="0 0 0" />
         <geometry>
            <mesh filename="package://ah_urdf/models/idx-F1.STL" />
         </geometry>
      </visual>
      <collision name="hand_index_mesh_coll_1">
         <origin rpy="0 0 0.0844739" xyz="0.0384727 0.0032577 0" />
         <geometry>
            <mesh filename="package://ah_urdf/models/idx-F1-hull.STL" />
         </geometry>
      </collision>
   </link>
   <link name="hand_index_L2">
      <inertial>
         <mass value="0.00600000" />
         <inertia ixx="4.06340451e-07" ixy="3.99862338e-07" ixz="-1.91966414e-09" iyy="9.13745257e-07" iyz="8.96846813e-10" izz="1.13382499e-06" />
         <origin xyz="1.52723400e-02 -1.00039197e-02 -3.11063902e-05" rpy="0 0 0" />
      </inertial>
      <visual name="hand_index_mesh_2">
         <origin rpy="0 0 0" xyz="0 0 0" />
         <geometry>
            <mesh filename="package://ah_urdf/models/idx-F2-Lg.STL" />
         </geometry>
      </visual>
      <collision name="hand_index_mesh_coll_2">
         <origin rpy="0 0 0" xyz="0.0091241 0 0" />
         <geometry>
            <mesh filename="package://ah_urdf/models/idx-F2-Lg-hull.STL" />
         </geometry>
      </collision>
   </link>
   <joint name="hand_index_q1" type="revolute">
      <parent link="hand_base" />
      <child link="hand_index_L1" />
      <origin xyz="-2.8e-2 -9e-3 9.6e-2" rpy=" 1.672 -1.317 -1.790 " />
      <axis xyz="0 0 1" />
      <limit lower="0" upper="2.00" effort="6.0" velocity="8.0677777442" />
      <dynamics damping="0.001" friction="0.001" />
   </joint>
   <joint name="hand_index_q2" type="revolute">
      <parent link="hand_index_L1" />
      <child link="hand_index_L2" />
      <origin xyz="38.472723e-3 3.257695e-3 0.000000e-3" rpy="0 0 0.766" />
      <axis xyz="0 0 1" />
      <limit lower="0.00" upper="1.844" effort="6.0" velocity="8.0677777442" />
      
      <dynamics damping="0.001" friction="0.001" />
      
      <mimic joint="index_q1" multiplier="0.814" />
   </joint>
   <link name="hand_index_anchor" />
   <joint name="hand_idx_anchor" type="fixed">
      <parent link="hand_index_L2" />
      <child link="hand_index_anchor" />
      <origin rpy="0 0 0" xyz="31.5541e-3  -10.44e-3 0.14e-3" />
   </joint>
   <link name="hand_fsr0" />
   <joint name="hand_fsr0" type="fixed">
      <parent link="hand_index_L2" />
      <child link="hand_fsr0" />
      <origin rpy="3.14 0 -0.1848" xyz="0.02936 -0.01697 -0.00435" />
   </joint>
   <link name="hand_fsr1" />
   <joint name="hand_fsr1" type="fixed">
      <parent link="hand_index_L2" />
      <child link="hand_fsr1" />
      <origin rpy="-1.5708 0.0 -0.2316" xyz="0.02961 -0.01394 0.0" />
   </joint>
   <link name="hand_fsr2" />
   <joint name="hand_fsr2" type="fixed">
      <parent link="hand_index_L2" />
      <child link="hand_fsr2" />
      <origin rpy="0.0 0.0 -0.1848036056311012" xyz="0.02936 -0.01697 0.00435" />
   </joint>
   <link name="hand_fsr3" />
   <joint name="hand_fsr3" type="fixed">
      <parent link="hand_index_L2" />
      <child link="hand_fsr3" />
      <origin rpy="3.14159 0.00000 -0.57092" xyz="0.01472 -0.01100 -0.00435" />
   </joint>
   <link name="hand_fsr4" />
   <joint name="hand_fsr4" type="fixed">
      <parent link="hand_index_L2" />
      <child link="hand_fsr4" />
      <origin rpy="0.00000 0.00000 -0.57199" xyz="0.01472 -0.01099 0.00435" />
   </joint>
   <link name="hand_fsr5" />
   <joint name="hand_fsr5" type="fixed">
      <parent link="hand_index_L2" />
      <child link="hand_fsr5" />
      <origin rpy="-2.66907 -1.57080 0.00000" xyz="0.03704 -0.01785 0.00000" />
   </joint>
   <link name="hand_middle_L1">
      <inertial>
         <mass value="0.00636000" />
         <inertia ixx="2.85169621e-07" ixy="1.21454801e-08" ixz="2.02098452e-09" iyy="9.77683041e-07" iyz="-2.87547802e-10" izz="1.05411544e-06" />
         <origin xyz="1.77549969e-02 -2.13867669e-04 -2.02851433e-05" rpy="0 0 0" />
      </inertial>
      <visual name="hand_middle_mesh_1">
         <origin rpy="0 0 0" xyz="0 0 0" />
         <geometry>
            <mesh filename="package://ah_urdf/models/idx-F1.STL" />
         </geometry>
      </visual>
      <collision name="hand_middle_mesh_coll_1">
         <origin rpy="0 0 0.0844739" xyz="0.0384727 0.0032577 0" />
         <geometry>
            <mesh filename="package://ah_urdf/models/idx-F1-hull.STL" />
         </geometry>
      </collision>
   </link>
   <link name="hand_middle_L2">
      <inertial>
         <mass value="0.00600000" />
         <inertia ixx="4.06340451e-07" ixy="3.99862338e-07" ixz="-1.91966414e-09" iyy="9.13745257e-07" iyz="8.96846813e-10" izz="1.13382499e-06" />
         <origin xyz="1.52723400e-02 -1.00039197e-02 -3.11063902e-05" rpy="0 0 0" />
      </inertial>
      <visual name="hand_middle_mesh_2">
         <origin rpy="0 0 0" xyz="0 0 0" />
         <geometry>
            <mesh filename="package://ah_urdf/models/idx-F2-Lg.STL" />
         </geometry>
      </visual>
      <collision name="hand_middle_mesh_coll_2">
         <origin rpy="0 0 0" xyz="0.0091241 0 0" />
         <geometry>
            <mesh filename="package://ah_urdf/models/idx-F2-Lg-hull.STL" />
         </geometry>
      </collision>
   </link>
   <joint name="hand_middle_q1" type="revolute">
      <parent link="hand_base" />
      <child link="hand_middle_L1" />
      <origin xyz=" -0.008 -0.012 0.099 " rpy=" 1.513 -1.322 -1.558 " />
      <limit lower="0" upper="2.00" effort="6.0" velocity="8.0677777442" />
      <dynamics damping="0.001" friction="0.001" />
      <axis xyz="0 0 1" />
   </joint>
   <joint name="hand_middle_q2" type="revolute">
      <parent link="hand_middle_L1" />
      <child link="hand_middle_L2" />
      <origin xyz="38.472723e-3 3.257695e-3 0.000000" rpy="0 0 0.766" />
      <axis xyz="0 0 1" />
      <limit lower="0.00" upper="1.844" effort="6.0" velocity="8.0677777442" />
      
      <dynamics damping="0.001" friction="0.001" />
      
      <mimic joint="middle_q1" multiplier="0.814" />
   </joint>
   <link name="hand_middle_anchor" />
   <joint name="hand_mid_anchor" type="fixed">
      <parent link="hand_middle_L2" />
      <child link="hand_middle_anchor" />
      <origin rpy="0 0 0" xyz="31.5541e-3  -10.44e-3 0.14e-3" />
   </joint>
   <link name="hand_fsr6" />
   <joint name="hand_fsr6" type="fixed">
      <parent link="hand_middle_L2" />
      <child link="hand_fsr6" />
      <origin rpy="3.14 0 -0.1848" xyz="0.02936 -0.01697 -0.00435" />
   </joint>
   <link name="hand_fsr7" />
   <joint name="hand_fsr7" type="fixed">
      <parent link="hand_middle_L2" />
      <child link="hand_fsr7" />
      <origin rpy="-1.5708 0.0 -0.2316" xyz="0.02961 -0.01394 0.0" />
   </joint>
   <link name="hand_fsr8" />
   <joint name="hand_fsr8" type="fixed">
      <parent link="hand_middle_L2" />
      <child link="hand_fsr8" />
      <origin rpy="0.0 0.0 -0.1848036056311012" xyz="0.02936 -0.01697 0.00435" />
   </joint>
   <link name="hand_fsr9" />
   <joint name="hand_fsr9" type="fixed">
      <parent link="hand_middle_L2" />
      <child link="hand_fsr9" />
      <origin rpy="3.14159 0.00000 -0.57092" xyz="0.01472 -0.01100 -0.00435" />
   </joint>
   <link name="hand_fsr10" />
   <joint name="hand_fsr10" type="fixed">
      <parent link="hand_middle_L2" />
      <child link="hand_fsr10" />
      <origin rpy="0.00000 0.00000 -0.57199" xyz="0.01472 -0.01099 0.00435" />
   </joint>
   <link name="hand_fsr11" />
   <joint name="hand_fsr11" type="fixed">
      <parent link="hand_middle_L2" />
      <child link="hand_fsr11" />
      <origin rpy="-2.66907 -1.57080 0.00000" xyz="0.03704 -0.01785 0.00000" />
   </joint>
   <link name="hand_ring_L1">
      <inertial>
         <mass value="0.00636000" />
         <inertia ixx="2.85169621e-07" ixy="1.21454801e-08" ixz="2.02098452e-09" iyy="9.77683041e-07" iyz="-2.87547802e-10" izz="1.05411544e-06" />
         <origin xyz="1.77549969e-02 -2.13867669e-04 -2.02851433e-05" rpy="0 0 0" />
      </inertial>
      <visual name="hand_ring_mesh_1">
         <origin rpy="0 0 0" xyz="0 0 0" />
         <geometry>
            <mesh filename="package://ah_urdf/models/idx-F1.STL" />
         </geometry>
      </visual>
      <collision name="hand_ring_mesh_coll_1">
         <origin rpy="0 0 0.0844739" xyz="0.0384727 0.0032577 0" />
         <geometry>
            <mesh filename="package://ah_urdf/models/idx-F1-hull.STL" />
         </geometry>
      </collision>
   </link>
   <link name="hand_ring_L2">
      <inertial>
         <mass value="0.00600000" />
         <inertia ixx="4.06340451e-07" ixy="3.99862338e-07" ixz="-1.91966414e-09" iyy="9.13745257e-07" iyz="8.96846813e-10" izz="1.13382499e-06" />
         <origin xyz="1.52723400e-02 -1.00039197e-02 -3.11063902e-05" rpy="0 0 0" />
      </inertial>
      <visual name="hand_ring_mesh_2">
         <origin rpy="0 0 0" xyz="0 0 0" />
         <geometry>
            <mesh filename="package://ah_urdf/models/idx-F2-Lg.STL" />
         </geometry>
      </visual>
      <collision name="hand_ring_mesh_coll_2">
         <origin rpy="0 0 0" xyz="0.0091241 0 0" />
         <geometry>
            <mesh filename="package://ah_urdf/models/idx-F2-Lg-hull.STL" />
         </geometry>
      </collision>
   </link>
   <joint name="hand_ring_q1" type="revolute">
      <parent link="hand_base" />
      <child link="hand_ring_L1" />
      <origin xyz=" 0.012 -0.010 0.097 " rpy=" 1.361 -1.315 -1.330 " />
      <limit lower="0" upper="2.00" effort="6.0" velocity="8.0677777442" />
      <dynamics damping="0.001" friction="0.001" />
      <axis xyz="0 0 1" />
   </joint>
   <joint name="hand_ring_q2" type="revolute">
      <parent link="hand_ring_L1" />
      <child link="hand_ring_L2" />
      <origin xyz="38.472723e-3 3.257695e-3 0.000000" rpy="0 0 0.766" />
      <axis xyz="0 0 1" />
      <limit lower="0.00" upper="1.844" effort="6.0" velocity="8.0677777442" />
      
      <dynamics damping="0.001" friction="0.001" />
      
      <mimic joint="ring_q1" multiplier="0.814" />
   </joint>
   <link name="hand_ring_anchor" />
   <joint name="hand_rng_anchor" type="fixed">
      <parent link="hand_ring_L2" />
      <child link="hand_ring_anchor" />
      <origin rpy="0 0 0" xyz="31.5541e-3  -10.44e-3 0.14e-3" />
   </joint>
   <link name="hand_fsr12" />
   <joint name="hand_fsr12" type="fixed">
      <parent link="hand_ring_L2" />
      <child link="hand_fsr12" />
      <origin rpy="3.14 0 -0.1848" xyz="0.02936 -0.01697 -0.00435" />
   </joint>
   <link name="hand_fsr13" />
   <joint name="hand_fsr13" type="fixed">
      <parent link="hand_ring_L2" />
      <child link="hand_fsr13" />
      <origin rpy="-1.5708 0.0 -0.2316" xyz="0.02961 -0.01394 0.0" />
   </joint>
   <link name="hand_fsr14" />
   <joint name="hand_fsr14" type="fixed">
      <parent link="hand_ring_L2" />
      <child link="hand_fsr14" />
      <origin rpy="0.0 0.0 -0.1848036056311012" xyz="0.02936 -0.01697 0.00435" />
   </joint>
   <link name="hand_fsr15" />
   <joint name="hand_fsr15" type="fixed">
      <parent link="hand_ring_L2" />
      <child link="hand_fsr15" />
      <origin rpy="3.14159 0.00000 -0.57092" xyz="0.01472 -0.01100 -0.00435" />
   </joint>
   <link name="hand_fsr16" />
   <joint name="hand_fsr16" type="fixed">
      <parent link="hand_ring_L2" />
      <child link="hand_fsr16" />
      <origin rpy="0.00000 0.00000 -0.57199" xyz="0.01472 -0.01099 0.00435" />
   </joint>
   <link name="hand_fsr17" />
   <joint name="hand_fsr17" type="fixed">
      <parent link="hand_ring_L2" />
      <child link="hand_fsr17" />
      <origin rpy="-2.66907 -1.57080 0.00000" xyz="0.03704 -0.01785 0.00000" />
   </joint>
   <link name="hand_pinky_L1">
      <inertial>
         <mass value="0.00636000" />
         <inertia ixx="2.85169621e-07" ixy="1.21454801e-08" ixz="2.02098452e-09" iyy="9.77683041e-07" iyz="-2.87547802e-10" izz="1.05411544e-06" />
         <origin xyz="1.77549969e-02 -2.13867669e-04 -2.02851433e-05" rpy="0 0 0" />
      </inertial>
      <visual name="hand_pinky_mesh_1">
         <origin rpy="0 0 0" xyz="0 0 0" />
         <geometry>
            <mesh filename="package://ah_urdf/models/idx-F1.STL" />
         </geometry>
      </visual>
      <collision name="hand_pinky_mesh_coll_1">
         <origin rpy="0 0 0.0844739" xyz="0.0384727 0.0032577 0" />
         <geometry>
            <mesh filename="package://ah_urdf/models/idx-F1-hull.STL" />
         </geometry>
      </collision>
   </link>
   <link name="hand_pinky_L2">
      <inertial>
         <mass value="0.00600000" />
         <inertia ixx="3.07970159e-07" ixy="2.80921010e-07" ixz="-2.72117073e-09" iyy="7.40775495e-07" iyz="1.08144438e-09" izz="8.93728844e-07" />
         <origin xyz="1.33249215e-02 -8.15894775e-03 -4.07689501e-05" rpy="0 0 0" />
      </inertial>
      <visual name="hand_pinky_mesh_2">
         <origin rpy="0 0 0" xyz="0 0 0" />
         <geometry>
            <mesh filename="package://ah_urdf/models/idx-F2.STL" />
         </geometry>
      </visual>
      <collision name="hand_pinky_mesh_coll_2">
         <origin rpy="0 0 0" xyz="0.0091241 0 0" />
         <geometry>
            <mesh filename="package://ah_urdf/models/idx-F2-hull.STL" />
         </geometry>
      </collision>
   </link>
   <joint name="hand_pinky_q1" type="revolute">
      <parent link="hand_base" />
      <child link="hand_pinky_L1" />
      <origin xyz=" 0.031 -0.007 0.091 " rpy=" 1.410 -1.315 -1.313 " />
      <limit lower="0" upper="2.00" effort="6.0" velocity="8.0677777442" />
      <dynamics damping="0.001" friction="0.001" />
      <axis xyz="0 0 1" />
   </joint>
   <joint name="hand_pinky_q2" type="revolute">
      <parent link="hand_pinky_L1" />
      <child link="hand_pinky_L2" />
      <origin xyz="38.472723e-3 3.257695e-3 0.000000" rpy="0 0 0.766" />
      <limit lower="0.00" upper="1.844" effort="6.0" velocity="8.0677777442" />
      
      <dynamics damping="0.001" friction="0.001" />
      
      <axis xyz="0 0 1" />
      <mimic joint="pinky_q1" multiplier="0.814" />
   </joint>
   <link name="hand_pinky_anchor" />
   <joint name="hand_pnky_anchor" type="fixed">
      <parent link="hand_pinky_L2" />
      <child link="hand_pinky_anchor" />
      <origin rpy="0 0 0" xyz="31.5541e-3  -10.44e-3 0.14e-3" />
   </joint>
   <link name="hand_fsr18" />
   <joint name="hand_fsr18" type="fixed">
      <parent link="hand_pinky_L2" />
      <child link="hand_fsr18" />
      <origin rpy="3.14 0 -0.1848" xyz="0.02556 -0.01391 -0.00435" />
   </joint>
   <link name="hand_fsr19" />
   <joint name="hand_fsr19" type="fixed">
      <parent link="hand_pinky_L2" />
      <child link="hand_fsr19" />
      <origin rpy="-1.5708 0.0 -0.2316" xyz="0.02517 -0.01110 -0.00000" />
   </joint>
   <link name="hand_fsr20" />
   <joint name="hand_fsr20" type="fixed">
      <parent link="hand_pinky_L2" />
      <child link="hand_fsr20" />
      <origin rpy="0.0 0.0 -0.1848036056311012" xyz="0.02556 -0.01391 0.00435" />
   </joint>
   <link name="hand_fsr21" />
   <joint name="hand_fsr21" type="fixed">
      <parent link="hand_pinky_L2" />
      <child link="hand_fsr21" />
      <origin rpy="3.14159 0.00000 -0.57092" xyz="0.01310 -0.00943 -0.00435" />
   </joint>
   <link name="hand_fsr22" />
   <joint name="hand_fsr22" type="fixed">
      <parent link="hand_pinky_L2" />
      <child link="hand_fsr22" />
      <origin rpy="0.00000 0.00000 -0.57199" xyz="0.01310 -0.00943 0.00435" />
   </joint>
   <link name="hand_fsr23" />
   <joint name="hand_fsr23" type="fixed">
      <parent link="hand_pinky_L2" />
      <child link="hand_fsr23" />
      <origin rpy="-2.66907 -1.57080 0.00000" xyz="0.03142 -0.01438 0.00000" />
   </joint>
   <link name="hand_thumb_L1">
      <inertial>
         <mass value="0.00200000" />
         <inertia ixx="1.19399127e-07" ixy="1.99799715e-08" ixz="-6.88490629e-08" iyy="2.50792788e-07" iyz="8.36717975e-09" izz="2.02280286e-07" />
         <origin xyz="1.42940200e-02 -1.88850000e-03 4.96979000e-03" rpy="0 0 0" />
      </inertial>
      <visual name="hand_thumb_mesh_1">
         <origin rpy="0 0 0" xyz="0 0 0" />
         <geometry>
            <mesh filename="package://ah_urdf/models/thumb-F1-MIR.STL" />
         </geometry>
      </visual>
      <collision name="hand_thumb_coll_mesh_1">
         <origin rpy="1.832596 0 0" xyz="0.0278284 0 0.0147507" />
         <geometry>
            <mesh filename="package://ah_urdf/models/thumb-F1-MIR-hull.STL" />
         </geometry>
      </collision>
   </link>
   <link name="hand_thumb_L2">
      <inertial>
         <mass value="0.06000000" />
         <inertia ixx="8.10858569e-06" ixy="-7.50865328e-06" ixz="-6.23786727e-08" iyy="2.16060955e-05" iyz="-1.00037755e-07" izz="2.58546348e-05" />
         <origin xyz="2.77624500e-02 5.62171000e-03 3.76111000e-03" rpy="0 0 0" />
      </inertial>
      <visual name="hand_thumb_mesh_2">
         <origin rpy="0 0 0" xyz="0 0 0" />
         <geometry>
            <mesh filename="package://ah_urdf/models/thumb-F2-right.STL" />
         </geometry>
      </visual>
      <collision name="hand_thumb_hull_mesh_2">
         <origin rpy="-3.141592 0 0.3438291" xyz="0.0651867 0.0233402 0.00393483" />
         <geometry>
            <mesh filename="package://ah_urdf/models/thumb-F2-hull.STL" />
         </geometry>
      </collision>
   </link>
   <joint name="hand_thumb_q1" type="revolute">
      <parent link="hand_base" />
      <child link="hand_thumb_L1" />
      <origin xyz="-24.0476665e-3 3.78124745e-3 32.32964923e-3" rpy="-0.01675973 -0.08689062 -2.95079797" />
      <axis xyz="0 0 1" />
      <limit lower="-2.00" upper="0" effort="1.2" velocity="40.338888721" />
      
      <dynamics damping="0.001" friction="0.001" />
      
   </joint>
   <joint name="hand_thumb_q2" type="revolute">
      <parent link="hand_thumb_L1" />
      <child link="hand_thumb_L2" />
      <origin xyz=" 27.8283501e-3 1.7436510745838653e-19 14.7507e-3 " rpy=" 1.832595714594045 -0.0 5.366520605522463e-18 " />
      <axis xyz="0 0 1" />
      <limit lower="0" upper="2.00" effort="6.0" velocity="8.0677777442" />
      
      <dynamics damping="0.001" friction="0.001" />
      
   </joint>
   <link name="hand_thumb_anchor" />
   <joint name="hand_thmb_anchor" type="fixed">
      <parent link="hand_thumb_L2" />
      <child link="hand_thumb_anchor" />
      <origin rpy="0 0 0" xyz="52.00122724e-3 28.00869333e-3 6.98483578e-3" />
   </joint>
   <link name="hand_fsr24" />
   <joint name="hand_fsr24" type="fixed">
      <parent link="hand_thumb_L2" />
      <child link="hand_fsr24" />
      <origin rpy="-2.29074 0.00001 0.41769" xyz="0.04747 0.01988 -0.001239" />
   </joint>
   <link name="hand_fsr25" />
   <joint name="hand_fsr25" type="fixed">
      <parent link="hand_thumb_L2" />
      <child link="hand_fsr25" />
      <origin rpy="-1.30899 0.00001 0.41769" xyz="0.04721 0.02124 0.006439" />
   </joint>
   <link name="hand_fsr26" />
   <joint name="hand_fsr26" type="fixed">
      <parent link="hand_thumb_L2" />
      <child link="hand_fsr26" />
      <origin rpy="-0.32726 0.00001 0.41769" xyz="0.04896 0.01654 0.01241" />
   </joint>
   <link name="hand_fsr27" />
   <joint name="hand_fsr27" type="fixed">
      <parent link="hand_thumb_L2" />
      <child link="hand_fsr27" />
      <origin rpy="-2.29074 0.00001 0.41769" xyz="0.03739 0.01536 -0.001289" />
   </joint>
   <link name="hand_fsr28" />
   <joint name="hand_fsr28" type="fixed">
      <parent link="hand_thumb_L2" />
      <child link="hand_fsr28" />
      <origin rpy="-0.32726 0.00001 0.41769" xyz="0.03888 0.01200 0.01244" />
   </joint>
   <link name="hand_fsr29" />
   <joint name="hand_fsr29" type="fixed">
      <parent link="hand_thumb_L2" />
      <child link="hand_fsr29" />
      <origin rpy="-1.39339 0.19354 -0.40280" xyz="0.05591 0.02160 0.00558" />
   </joint>
<joint name="base_link_to_base" type="fixed"><parent link="hand_base_link" /><child link="hand_base" /><origin xyz="0 0 0" /></joint></robot>